Workbook

Sheet Metrics Ranking
A1: Scoring Rubric
B2: Fund | C2: Returns Score | D2: Standard Deviation Score | E2: Mgmt and Org Score | F2: Cost Structure Score | G2: Average Score | H2: Rank
B3: ='Analysis I'!B3 -> Parag Parikh Flexi Cap Fund - Regular Plan - Growth | C3: =_xlfn.XLOOKUP($B3,'Analysis I'!$B$3:$B$25,'Analysis I'!F$3:F$25) -> 9.54 | D3: =_xlfn.XLOOKUP($B3,'Analysis I'!$B$3:$B$25,'Analysis I'!G$3:G$25) -> 10 | E3: =_xlfn.XLOOKUP($B3,'Analysis II'!$G$3:$G$25,'Analysis II'!T$3:T$25) -> 8 | F3: =_xlfn.XLOOKUP($B3,'Analysis II'!$G$3:$G$25,'Analysis II'!U$3:U$25) -> 5.91 | G3: =AVERAGE(C3:F3) -> 8.3625 | H3: =_xlfn.RANK.AVG(G3,$G$3:$G$25,0) -> 1
B4: ='Analysis I'!B7 -> Franklin India Flexi Cap Fund - Growth | C4: =_xlfn.XLOOKUP($B4,'Analysis I'!$B$3:$B$25,'Analysis I'!F$3:F$25) -> 8.18 | D4: =_xlfn.XLOOKUP($B4,'Analysis I'!$B$3:$B$25,'Analysis I'!G$3:G$25) -> 3.64 | E4: =_xlfn.XLOOKUP($B4,'Analysis II'!$G$3:$G$25,'Analysis II'!T$3:T$25) -> 7.3333333 | F4: =_xlfn.XLOOKUP($B4,'Analysis II'!$G$3:$G$25,'Analysis II'!U$3:U$25) -> 9.55 | G4: =AVERAGE(C4:F4) -> 7.1758333 | H4: =_xlfn.RANK.AVG(G4,$G$3:$G$25,0) -> 2
B5: ='Analysis I'!B12 -> Edelweiss Flexi Cap Fund - Regular Plan - Growth Option | C5: =_xlfn.XLOOKUP($B5,'Analysis I'!$B$3:$B$25,'Analysis I'!F$3:F$25) -> 6.36 | D5: =_xlfn.XLOOKUP($B5,'Analysis I'!$B$3:$B$25,'Analysis I'!G$3:G$25) -> 4.55 | E5: =_xlfn.XLOOKUP($B5,'Analysis II'!$G$3:$G$25,'Analysis II'!T$3:T$25) -> 8.6666667 | F5: =_xlfn.XLOOKUP($B5,'Analysis II'!$G$3:$G$25,'Analysis II'!U$3:U$25) -> 8.64 | G5: =AVERAGE(C5:F5) -> 7.0541667 | H5: =_xlfn.RANK.AVG(G5,$G$3:$G$25,0) -> 3
B6: ='Analysis I'!B10 -> DSP Flexi Cap Fund - Regular Plan - Growth | C6: =_xlfn.XLOOKUP($B6,'Analysis I'!$B$3:$B$25,'Analysis I'!F$3:F$25) -> 6.81 | D6: =_xlfn.XLOOKUP($B6,'Analysis I'!$B$3:$B$25,'Analysis I'!G$3:G$25) -> 5.46 | E6: =_xlfn.XLOOKUP($B6,'Analysis II'!$G$3:$G$25,'Analysis II'!T$3:T$25) -> 5.3333333 | F6: =_xlfn.XLOOKUP($B6,'Analysis II'!$G$3:$G$25,'Analysis II'!U$3:U$25) -> 10 | G6: =AVERAGE(C6:F6) -> 6.9008333 | H6: =_xlfn.RANK.AVG(G6,$G$3:$G$25,0) -> 4
B7: ='Analysis I'!B9 -> Union Flexi Cap Fund - Growth Option | C7: =_xlfn.XLOOKUP($B7,'Analysis I'!$B$3:$B$25,'Analysis I'!F$3:F$25) -> 7.27 | D7: =_xlfn.XLOOKUP($B7,'Analysis I'!$B$3:$B$25,'Analysis I'!G$3:G$25) -> 6.37 | E7: =_xlfn.XLOOKUP($B7,'Analysis II'!$G$3:$G$25,'Analysis II'!T$3:T$25) -> 6 | F7: =_xlfn.XLOOKUP($B7,'Analysis II'!$G$3:$G$25,'Analysis II'!U$3:U$25) -> 6.37 | G7: =AVERAGE(C7:F7) -> 6.5025 | H7: =_xlfn.RANK.AVG(G7,$G$3:$G$25,0) -> 5
B8: ='Analysis I'!B6 -> HDFC Flexi Cap Fund - Growth Plan | C8: =_xlfn.XLOOKUP($B8,'Analysis I'!$B$3:$B$25,'Analysis I'!F$3:F$25) -> 8.63 | D8: =_xlfn.XLOOKUP($B8,'Analysis I'!$B$3:$B$25,'Analysis I'!G$3:G$25) -> 2.73 | E8: =_xlfn.XLOOKUP($B8,'Analysis II'!$G$3:$G$25,'Analysis II'!T$3:T$25) -> 7.3333333 | F8: =_xlfn.XLOOKUP($B8,'Analysis II'!$G$3:$G$25,'Analysis II'!U$3:U$25) -> 7.28 | G8: =AVERAGE(C8:F8) -> 6.4933333 | H8: =_xlfn.RANK.AVG(G8,$G$3:$G$25,0) -> 6
B9: ='Analysis I'!B20 -> BANDHAN Flexi Cap Fund - Regular Plan - Growth | C9: =_xlfn.XLOOKUP($B9,'Analysis I'!$B$3:$B$25,'Analysis I'!F$3:F$25) -> 1.36 | D9: =_xlfn.XLOOKUP($B9,'Analysis I'!$B$3:$B$25,'Analysis I'!G$3:G$25) -> 8.19 | E9: =_xlfn.XLOOKUP($B9,'Analysis II'!$G$3:$G$25,'Analysis II'!T$3:T$25) -> 6.6666667 | F9: =_xlfn.XLOOKUP($B9,'Analysis II'!$G$3:$G$25,'Analysis II'!U$3:U$25) -> 9.1 | G9: =AVERAGE(C9:F9) -> 6.3291667 | H9: =_xlfn.RANK.AVG(G9,$G$3:$G$25,0) -> 7
B10: ='Analysis I'!B4 -> quant Flexi Cap Fund - Growth Option - Regular Plan | C10: =_xlfn.XLOOKUP($B10,'Analysis I'!$B$3:$B$25,'Analysis I'!F$3:F$25) -> 10 | D10: =_xlfn.XLOOKUP($B10,'Analysis I'!$B$3:$B$25,'Analysis I'!G$3:G$25) -> 0 | E10: =_xlfn.XLOOKUP($B10,'Analysis II'!$G$3:$G$25,'Analysis II'!T$3:T$25) -> 8.6666667 | F10: =_xlfn.XLOOKUP($B10,'Analysis II'!$G$3:$G$25,'Analysis II'!U$3:U$25) -> 5.91 | G10: =AVERAGE(C10:F10) -> 6.1441667 | H10: =_xlfn.RANK.AVG(G10,$G$3:$G$25,0) -> 8
B11: ='Analysis I'!B15 -> UTI - Flexi Cap Fund-Growth Option | C11: =_xlfn.XLOOKUP($B11,'Analysis I'!$B$3:$B$25,'Analysis I'!F$3:F$25) -> 4.54 | D11: =_xlfn.XLOOKUP($B11,'Analysis I'!$B$3:$B$25,'Analysis I'!G$3:G$25) -> 8.64 | E11: =_xlfn.XLOOKUP($B11,'Analysis II'!$G$3:$G$25,'Analysis II'!T$3:T$25) -> 7.3333333 | F11: =_xlfn.XLOOKUP($B11,'Analysis II'!$G$3:$G$25,'Analysis II'!U$3:U$25) -> 3.19 | G11: =AVERAGE(C11:F11) -> 5.9258333 | H11: =_xlfn.RANK.AVG(G11,$G$3:$G$25,0) -> 9
B12: ='Analysis I'!B18 -> SBI Flexicap Fund - REGULAR PLAN -Growth Option | C12: =_xlfn.XLOOKUP($B12,'Analysis I'!$B$3:$B$25,'Analysis I'!F$3:F$25) -> 1.81 | D12: =_xlfn.XLOOKUP($B12,'Analysis I'!$B$3:$B$25,'Analysis I'!G$3:G$25) -> 9.55 | E12: =_xlfn.XLOOKUP($B12,'Analysis II'!$G$3:$G$25,'Analysis II'!T$3:T$25) -> 8 | F12: =_xlfn.XLOOKUP($B12,'Analysis II'!$G$3:$G$25,'Analysis II'!U$3:U$25) -> 3.64 | G12: =AVERAGE(C12:F12) -> 5.75 | H12: =_xlfn.RANK.AVG(G12,$G$3:$G$25,0) -> 10
B13: ='Analysis I'!B8 -> PGIM India Flexi Cap Fund - Regular Plan - Growth Option | C13: =_xlfn.XLOOKUP($B13,'Analysis I'!$B$3:$B$25,'Analysis I'!F$3:F$25) -> 7.72 | D13: =_xlfn.XLOOKUP($B13,'Analysis I'!$B$3:$B$25,'Analysis I'!G$3:G$25) -> 5.91 | E13: =_xlfn.XLOOKUP($B13,'Analysis II'!$G$3:$G$25,'Analysis II'!T$3:T$25) -> 6.6666667 | F13: =_xlfn.XLOOKUP($B13,'Analysis II'!$G$3:$G$25,'Analysis II'!U$3:U$25) -> 2.28 | G13: =AVERAGE(C13:F13) -> 5.6441667 | H13: =_xlfn.RANK.AVG(G13,$G$3:$G$25,0) -> 11
B14: ='Analysis I'!B17 -> Kotak Flexicap Fund - Growth | C14: =_xlfn.XLOOKUP($B14,'Analysis I'!$B$3:$B$25,'Analysis I'!F$3:F$25) -> 4.09 | D14: =_xlfn.XLOOKUP($B14,'Analysis I'!$B$3:$B$25,'Analysis I'!G$3:G$25) -> 2.28 | E14: =_xlfn.XLOOKUP($B14,'Analysis II'!$G$3:$G$25,'Analysis II'!T$3:T$25) -> 8 | F14: =_xlfn.XLOOKUP($B14,'Analysis II'!$G$3:$G$25,'Analysis II'!U$3:U$25) -> 7.28 | G14: =AVERAGE(C14:F14) -> 5.4125 | H14: =_xlfn.RANK.AVG(G14,$G$3:$G$25,0) -> 12
B15: ='Analysis I'!B19 -> Axis Flexi Cap Fund - Regular Plan - Growth | C15: =_xlfn.XLOOKUP($B15,'Analysis I'!$B$3:$B$25,'Analysis I'!F$3:F$25) -> 2.72 | D15: =_xlfn.XLOOKUP($B15,'Analysis I'!$B$3:$B$25,'Analysis I'!G$3:G$25) -> 7.28 | E15: =_xlfn.XLOOKUP($B15,'Analysis II'!$G$3:$G$25,'Analysis II'!T$3:T$25) -> 5.3333333 | F15: =_xlfn.XLOOKUP($B15,'Analysis II'!$G$3:$G$25,'Analysis II'!U$3:U$25) -> 5 | G15: =AVERAGE(C15:F15) -> 5.0833333 | H15: =_xlfn.RANK.AVG(G15,$G$3:$G$25,0) -> 13
B16: ='Analysis I'!B14 -> HSBC Flexi Cap Fund - Regular Growth | C16: =_xlfn.XLOOKUP($B16,'Analysis I'!$B$3:$B$25,'Analysis I'!F$3:F$25) -> 5.9 | D16: =_xlfn.XLOOKUP($B16,'Analysis I'!$B$3:$B$25,'Analysis I'!G$3:G$25) -> 1.37 | E16: =_xlfn.XLOOKUP($B16,'Analysis II'!$G$3:$G$25,'Analysis II'!T$3:T$25) -> 4.6666667 | F16: =_xlfn.XLOOKUP($B16,'Analysis II'!$G$3:$G$25,'Analysis II'!U$3:U$25) -> 8.19 | G16: =AVERAGE(C16:F16) -> 5.0316667 | H16: =_xlfn.RANK.AVG(G16,$G$3:$G$25,0) -> 14
B17: ='Analysis I'!B11 -> CANARA ROBECO FLEXICAP FUND - REGULAR PLAN - GROWTH OPTION | C17: =_xlfn.XLOOKUP($B17,'Analysis I'!$B$3:$B$25,'Analysis I'!F$3:F$25) -> 5.45 | D17: =_xlfn.XLOOKUP($B17,'Analysis I'!$B$3:$B$25,'Analysis I'!G$3:G$25) -> 7.73 | E17: =_xlfn.XLOOKUP($B17,'Analysis II'!$G$3:$G$25,'Analysis II'!T$3:T$25) -> 6 | F17: =_xlfn.XLOOKUP($B17,'Analysis II'!$G$3:$G$25,'Analysis II'!U$3:U$25) -> 0.91 | G17: =AVERAGE(C17:F17) -> 5.0225 | H17: =_xlfn.RANK.AVG(G17,$G$3:$G$25,0) -> 15
B18: ='Analysis I'!B16 -> Tata Flexi Cap Fund -Regular Plan-Growth | C18: =_xlfn.XLOOKUP($B18,'Analysis I'!$B$3:$B$25,'Analysis I'!F$3:F$25) -> 3.18 | D18: =_xlfn.XLOOKUP($B18,'Analysis I'!$B$3:$B$25,'Analysis I'!G$3:G$25) -> 9.1 | E18: =_xlfn.XLOOKUP($B18,'Analysis II'!$G$3:$G$25,'Analysis II'!T$3:T$25) -> 4 | F18: =_xlfn.XLOOKUP($B18,'Analysis II'!$G$3:$G$25,'Analysis II'!U$3:U$25) -> 3.19 | G18: =AVERAGE(C18:F18) -> 4.8675 | H18: =_xlfn.RANK.AVG(G18,$G$3:$G$25,0) -> 16
B19: ='Analysis I'!B13 -> Aditya Birla Sun Life Flexi Cap Fund - Growth - Regular Plan | C19: =_xlfn.XLOOKUP($B19,'Analysis I'!$B$3:$B$25,'Analysis I'!F$3:F$25) -> 5 | D19: =_xlfn.XLOOKUP($B19,'Analysis I'!$B$3:$B$25,'Analysis I'!G$3:G$25) -> 3.19 | E19: =_xlfn.XLOOKUP($B19,'Analysis II'!$G$3:$G$25,'Analysis II'!T$3:T$25) -> 6.6666667 | F19: =_xlfn.XLOOKUP($B19,'Analysis II'!$G$3:$G$25,'Analysis II'!U$3:U$25) -> 4.55 | G19: =AVERAGE(C19:F19) -> 4.8516667 | H19: =_xlfn.RANK.AVG(G19,$G$3:$G$25,0) -> 17
B20: ='Analysis I'!B23 -> LIC MF Flexi Cap Fund-Regular Plan-Growth | C20: =_xlfn.XLOOKUP($B20,'Analysis I'!$B$3:$B$25,'Analysis I'!F$3:F$25) -> 0.45 | D20: =_xlfn.XLOOKUP($B20,'Analysis I'!$B$3:$B$25,'Analysis I'!G$3:G$25) -> 6.82 | E20: =_xlfn.XLOOKUP($B20,'Analysis II'!$G$3:$G$25,'Analysis II'!T$3:T$25) -> 3.3333333 | F20: =_xlfn.XLOOKUP($B20,'Analysis II'!$G$3:$G$25,'Analysis II'!U$3:U$25) -> 7.73 | G20: =AVERAGE(C20:F20) -> 4.5833333 | H20: =_xlfn.RANK.AVG(G20,$G$3:$G$25,0) -> 18
B21: ='Analysis I'!B5 -> JM Flexicap Fund (Regular) - Growth option | C21: =_xlfn.XLOOKUP($B21,'Analysis I'!$B$3:$B$25,'Analysis I'!F$3:F$25) -> 9.09 | D21: =_xlfn.XLOOKUP($B21,'Analysis I'!$B$3:$B$25,'Analysis I'!G$3:G$25) -> 0.91 | E21: =_xlfn.XLOOKUP($B21,'Analysis II'!$G$3:$G$25,'Analysis II'!T$3:T$25) -> 6 | F21: =_xlfn.XLOOKUP($B21,'Analysis II'!$G$3:$G$25,'Analysis II'!U$3:U$25) -> 1.37 | G21: =AVERAGE(C21:F21) -> 4.3425 | H21: =_xlfn.RANK.AVG(G21,$G$3:$G$25,0) -> 19
B22: ='Analysis I'!B22 -> Navi Flexi Cap Fund - Regular Plan - Growth | C22: =_xlfn.XLOOKUP($B22,'Analysis I'!$B$3:$B$25,'Analysis I'!F$3:F$25) -> 2.27 | D22: =_xlfn.XLOOKUP($B22,'Analysis I'!$B$3:$B$25,'Analysis I'!G$3:G$25) -> 5 | E22: =_xlfn.XLOOKUP($B22,'Analysis II'!$G$3:$G$25,'Analysis II'!T$3:T$25) -> 4.6666667 | F22: =_xlfn.XLOOKUP($B22,'Analysis II'!$G$3:$G$25,'Analysis II'!U$3:U$25) -> 4.55 | G22: =AVERAGE(C22:F22) -> 4.1216667 | H22: =_xlfn.RANK.AVG(G22,$G$3:$G$25,0) -> 20
B23: ='Analysis I'!B21 -> Motilal Oswal Flexi Cap Fund Regular Plan-Growth Option | C23: =_xlfn.XLOOKUP($B23,'Analysis I'!$B$3:$B$25,'Analysis I'!F$3:F$25) -> 3.63 | D23: =_xlfn.XLOOKUP($B23,'Analysis I'!$B$3:$B$25,'Analysis I'!G$3:G$25) -> 0.46 | E23: =_xlfn.XLOOKUP($B23,'Analysis II'!$G$3:$G$25,'Analysis II'!T$3:T$25) -> 4 | F23: =_xlfn.XLOOKUP($B23,'Analysis II'!$G$3:$G$25,'Analysis II'!U$3:U$25) -> 0.46 | G23: =AVERAGE(C23:F23) -> 2.1375 | H23: =_xlfn.RANK.AVG(G23,$G$3:$G$25,0) -> 21
B24: ='Analysis I'!B24 -> Taurus Flexi Cap Fund - Regular Plan - Growth | C24: =_xlfn.XLOOKUP($B24,'Analysis I'!$B$3:$B$25,'Analysis I'!F$3:F$25) -> 0.9 | D24: =_xlfn.XLOOKUP($B24,'Analysis I'!$B$3:$B$25,'Analysis I'!G$3:G$25) -> 1.82 | E24: =_xlfn.XLOOKUP($B24,'Analysis II'!$G$3:$G$25,'Analysis II'!T$3:T$25) -> 3.3333333 | F24: =_xlfn.XLOOKUP($B24,'Analysis II'!$G$3:$G$25,'Analysis II'!U$3:U$25) -> 1.82 | G24: =AVERAGE(C24:F24) -> 1.9683333 | H24: =_xlfn.RANK.AVG(G24,$G$3:$G$25,0) -> 22
B25: ='Analysis I'!B25 -> Shriram Flexi Cap Fund - Regular Growth | C25: =_xlfn.XLOOKUP($B25,'Analysis I'!$B$3:$B$25,'Analysis I'!F$3:F$25) -> 0 | D25: =_xlfn.XLOOKUP($B25,'Analysis I'!$B$3:$B$25,'Analysis I'!G$3:G$25) -> 4.1 | E25: =_xlfn.XLOOKUP($B25,'Analysis II'!$G$3:$G$25,'Analysis II'!T$3:T$25) -> 3.3333333 | F25: =_xlfn.XLOOKUP($B25,'Analysis II'!$G$3:$G$25,'Analysis II'!U$3:U$25) -> 0 | G25: =AVERAGE(C25:F25) -> 1.8583333 | H25: =_xlfn.RANK.AVG(G25,$G$3:$G$25,0) -> 23

Sheet Analysis I
A1: Mean and Standard Deviation
B2: Fund | C2: Returns | D2: SD | E2: Sharpe | F2: Mean Score | G2: SD Score | H2: Sharpe Score
B3: Parag Parikh Flexi Cap Fund - Regular Plan - Growth | C3: 0.20322351 | D3: 0.13427477 | E3: 1.0145131 | F3: =_xlfn.PERCENTRANK.INC(C$3:C$25,C3)*10 -> 9.54 | G3: =10 - _xlfn.PERCENTRANK.INC(D$3:D$25,D3)*10 -> 10 | H3: =_xlfn.PERCENTRANK.INC(E$3:E$25,E3)*10 -> 10
B4: quant Flexi Cap Fund - Growth Option - Regular Plan | C4: 0.23563362 | D4: 0.18751201 | E4: 0.8993217 | F4: =_xlfn.PERCENTRANK.INC(C$3:C$25,C4)*10 -> 10 | G4: =10 - _xlfn.PERCENTRANK.INC(D$3:D$25,D4)*10 -> 0 | H4: =_xlfn.PERCENTRANK.INC(E$3:E$25,E4)*10 -> 9.54
B5: JM Flexicap Fund (Regular) - Growth option | C5: 0.20058082 | D5: 0.17904218 | E5: 0.74608576 | F5: =_xlfn.PERCENTRANK.INC(C$3:C$25,C5)*10 -> 9.09 | G5: =10 - _xlfn.PERCENTRANK.INC(D$3:D$25,D5)*10 -> 0.91 | H5: =_xlfn.PERCENTRANK.INC(E$3:E$25,E5)*10 -> 9.09
B6: HDFC Flexi Cap Fund - Growth Plan | C6: 0.18572544 | D6: 0.16991156 | E6: 0.69874847 | F6: =_xlfn.PERCENTRANK.INC(C$3:C$25,C6)*10 -> 8.63 | G6: =10 - _xlfn.PERCENTRANK.INC(D$3:D$25,D6)*10 -> 2.73 | H6: =_xlfn.PERCENTRANK.INC(E$3:E$25,E6)*10 -> 8.63
B7: Franklin India Flexi Cap Fund - Growth | C7: 0.17442254 | D7: 0.16811446 | E7: 0.63898452 | F7: =_xlfn.PERCENTRANK.INC(C$3:C$25,C7)*10 -> 8.18 | G7: =10 - _xlfn.PERCENTRANK.INC(D$3:D$25,D7)*10 -> 3.64 | H7: =_xlfn.PERCENTRANK.INC(E$3:E$25,E7)*10 -> 8.18
B8: PGIM India Flexi Cap Fund - Regular Plan - Growth Option | C8: 0.16850476 | D8: 0.16465236 | E8: 0.61647923 | F8: =_xlfn.PERCENTRANK.INC(C$3:C$25,C8)*10 -> 7.72 | G8: =10 - _xlfn.PERCENTRANK.INC(D$3:D$25,D8)*10 -> 5.91 | H8: =_xlfn.PERCENTRANK.INC(E$3:E$25,E8)*10 -> 7.72
B9: Union Flexi Cap Fund - Growth Option | C9: 0.16428922 | D9: 0.160421 | E9: 0.60646185 | F9: =_xlfn.PERCENTRANK.INC(C$3:C$25,C9)*10 -> 7.27 | G9: =10 - _xlfn.PERCENTRANK.INC(D$3:D$25,D9)*10 -> 6.37 | H9: =_xlfn.PERCENTRANK.INC(E$3:E$25,E9)*10 -> 7.27
B10: DSP Flexi Cap Fund - Regular Plan - Growth | C10: 0.16327915 | D10: 0.1662646 | E10: 0.57907185 | F10: =_xlfn.PERCENTRANK.INC(C$3:C$25,C10)*10 -> 6.81 | G10: =10 - _xlfn.PERCENTRANK.INC(D$3:D$25,D10)*10 -> 5.46 | H10: =_xlfn.PERCENTRANK.INC(E$3:E$25,E10)*10 -> 6.81
B11: CANARA ROBECO FLEXICAP FUND - REGULAR PLAN - GROWTH OPTION | C11: 0.15710751 | D11: 0.15828132 | E11: 0.56928711 | F11: =_xlfn.PERCENTRANK.INC(C$3:C$25,C11)*10 -> 5.45 | G11: =10 - _xlfn.PERCENTRANK.INC(D$3:D$25,D11)*10 -> 7.73 | H11: =_xlfn.PERCENTRANK.INC(E$3:E$25,E11)*10 -> 6.36
B12: Edelweiss Flexi Cap Fund - Regular Plan - Growth Option | C12: 0.16119239 | D12: 0.16800426 | E12: 0.5606548 | F12: =_xlfn.PERCENTRANK.INC(C$3:C$25,C12)*10 -> 6.36 | G12: =10 - _xlfn.PERCENTRANK.INC(D$3:D$25,D12)*10 -> 4.55 | H12: =_xlfn.PERCENTRANK.INC(E$3:E$25,E12)*10 -> 5.9
B13: Aditya Birla Sun Life Flexi Cap Fund - Growth - Regular Plan | C13: 0.15589137 | D13: 0.16956257 | E13: 0.52423935 | F13: =_xlfn.PERCENTRANK.INC(C$3:C$25,C13)*10 -> 5 | G13: =10 - _xlfn.PERCENTRANK.INC(D$3:D$25,D13)*10 -> 3.19 | H13: =_xlfn.PERCENTRANK.INC(E$3:E$25,E13)*10 -> 5.45
B14: HSBC Flexi Cap Fund - Regular Growth | C14: 0.1604493 | D14: 0.17902811 | E14: 0.52198116 | F14: =_xlfn.PERCENTRANK.INC(C$3:C$25,C14)*10 -> 5.9 | G14: =10 - _xlfn.PERCENTRANK.INC(D$3:D$25,D14)*10 -> 1.37 | H14: =_xlfn.PERCENTRANK.INC(E$3:E$25,E14)*10 -> 5
... B25: Shriram Flexi Cap Fund - Regular Growth | C25: 0.11295283 | D25: 0.16806372 | E25: 0.27342501 | F25: =_xlfn.PERCENTRANK.INC(C$3:C$25,C25)*10 -> 0 | G25: =10 - _xlfn.PERCENTRANK.INC(D$3:D$25,D25)*10 -> 4.1 | H25: =_xlfn.PERCENTRANK.INC(E$3:E$25,E25)*10 -> 0

Sheet Analysis II
F1: Management & Organisation and Cost Structure | K1: Data: Value Research | N1: Data: Morningstar.in | Q1: Scoring Method
A2: Funds | B2: Expense Ratio (%) | C2: Launch | D2: Net Assets (Cr) | G2: Fund | I2: Alpha | J2: Beta | K2: =B2 -> Expense Ratio (%) | L2: =D2 -> Net Assets (Cr) | M2: MorningStar opinion | N2: Process | O2: People | P2: Parent | Q2: Process Score | R2: People Score | S2: Parent Score | T2: Mgmt and Org Score | U2: Cost Structure Score | W2: Code | X2: Score
A3: Aditya Birla Sun Life Flexi Cap Fund - Regular Plan | B3: 1.65 | C3: 36034 | D3: 25098 | G3: Edelweiss Flexi Cap Fund - Regular Plan - Growth Option | H3: Edelweiss Flexi Cap Fund - Regular Plan - Grow... | I3: 0.00062 | J3: -0.001128 | K3: =B3 -> 1.65 | L3: =D3 -> 25098 | M3: Bronze | N3: AA | O3: AA | P3: H | Q3: =_xlfn.XLOOKUP(N3,$W$3:$W$12,$X$3:$X$12) -> 8 | R3: =_xlfn.XLOOKUP(O3,$W$3:$W$12,$X$3:$X$12) -> 8 | S3: =_xlfn.XLOOKUP(P3,$W$3:$W$12,$X$3:$X$12) -> 10 | T3: =AVERAGE(Q3:S3) -> 8.6666667 | U3: =10 - _xlfn.PERCENTRANK.INC($K$3:$K$25,K3)*10 -> 8.64 | W3: L | X3: 2
A4: Axis Flexi Cap Fund - Regular Plan | B4: 1.72 | C4: 43059 | D4: 13026 | G4: quant Flexi Cap Fund - Growth Option - Regular Plan | H4: quant Flexi Cap Fund - Growth Option - Regular... | I4: 0.000839 | J4: -0.002762 | K4: =B4 -> 1.72 | L4: =D4 -> 13026 | M4: Gold | N4: H | O4: H | P4: A | Q4: =_xlfn.XLOOKUP(N4,$W$3:$W$12,$X$3:$X$12) -> 10 | R4: =_xlfn.XLOOKUP(O4,$W$3:$W$12,$X$3:$X$12) -> 10 | S4: =_xlfn.XLOOKUP(P4,$W$3:$W$12,$X$3:$X$12) -> 6 | T4: =AVERAGE(Q4:S4) -> 8.6666667 | U4: =10 - _xlfn.PERCENTRANK.INC($K$3:$K$25,K4)*10 -> 5.91 | W4: BA | X4: 4
A5: Bandhan Flexi Cap Fund - Regular Plan | B5: 1.85 | C5: 38623 | D5: 7708 | G5: SBI Flexicap Fund - REGULAR PLAN -Growth Option | H5: SBI Flexicap Fund - REGULAR PLAN -Growth Option | I5: 0.000544 | J5: -0.002341 | K5: =B5 -> 1.85 | L5: =D5 -> 7708 | M5: Bronze | N5: AA | O5: AA | P5: AA | Q5: =_xlfn.XLOOKUP(N5,$W$3:$W$12,$X$3:$X$12) -> 8 | R5: =_xlfn.XLOOKUP(O5,$W$3:$W$12,$X$3:$X$12) -> 8 | S5: =_xlfn.XLOOKUP(P5,$W$3:$W$12,$X$3:$X$12) -> 8 | T5: =AVERAGE(Q5:S5) -> 8 | U5: =10 - _xlfn.PERCENTRANK.INC($K$3:$K$25,K5)*10 -> 3.64 | W5: A | X5: 6
A6: Canara Robeco Flexi Cap Fund - Regular Plan | B6: 1.69 | C6: 37880 | D6: 13760 | G6: Kotak Flexicap Fund - Growth | H6: Kotak Flexicap Fund - Growth | I6: 0.000584 | J6: -0.002431 | K6: =B6 -> 1.69 | L6: =D6 -> 13760 | M6: Bronze | N6: AA | O6: AA | P6: AA | Q6: =_xlfn.XLOOKUP(N6,$W$3:$W$12,$X$3:$X$12) -> 8 | R6: =_xlfn.XLOOKUP(O6,$W$3:$W$12,$X$3:$X$12) -> 8 | S6: =_xlfn.XLOOKUP(P6,$W$3:$W$12,$X$3:$X$12) -> 8 | T6: =AVERAGE(Q6:S6) -> 8 | U6: =10 - _xlfn.PERCENTRANK.INC($K$3:$K$25,K6)*10 -> 7.28 | W6: AA | X6: 8
A7: DSP Flexi Cap Fund - Regular Plan | B7: 1.72 | C7: 35549 | D7: 12328 | G7: Parag Parikh Flexi Cap Fund - Regular Plan - Growth | H7: Parag Parikh Flexi Cap Fund - Regular Plan - G... | I7: 0.000754 | J7: -0.001281 | K7: =B7 -> 1.72 | L7: =D7 -> 12328 | M7: Bronze | N7: AA | O7: AA | P7: AA | Q7: =_xlfn.XLOOKUP(N7,$W$3:$W$12,$X$3:$X$12) -> 8 | R7: =_xlfn.XLOOKUP(O7,$W$3:$W$12,$X$3:$X$12) -> 8 | S7: =_xlfn.XLOOKUP(P7,$W$3:$W$12,$X$3:$X$12) -> 8 | T7: =AVERAGE(Q7:S7) -> 8 | U7: =10 - _xlfn.PERCENTRANK.INC($K$3:$K$25,K7)*10 -> 5.91 | W7: H | X7: 10
A8: Edelweiss Flexi Cap Fund - Regular Plan | B8: 1.89 | C8: 42038 | D8: 3127 | G8: UTI - Flexi Cap Fund-Growth Option | H8: UTI - Flexi Cap Fund-Growth Option | I8: 0.000571 | J8: -0.000148 | K8: =B8 -> 1.89 | L8: =D8 -> 3127 | M8: Bronze | N8: AA | O8: AA | P8: A | Q8: =_xlfn.XLOOKUP(N8,$W$3:$W$12,$X$3:$X$12) -> 8 | R8: =_xlfn.XLOOKUP(O8,$W$3:$W$12,$X$3:$X$12) -> 8 | S8: =_xlfn.XLOOKUP(P8,$W$3:$W$12,$X$3:$X$12) -> 6 | T8: =AVERAGE(Q8:S8) -> 7.3333333 | U8: =10 - _xlfn.PERCENTRANK.INC($K$3:$K$25,K8)*10 -> 3.19 | W8: Gold | X8: 10
A9: Franklin India Flexi Cap Fund - Regular Plan | B9: 1.69 | C9: 34606 | D9: 19972 | G9: HDFC Flexi Cap Fund - Growth Plan | H9: HDFC Flexi Cap Fund - Growth Plan | I9: 0.000731 | J9: -0.002641 | K9: =B9 -> 1.69 | L9: =D9 -> 19972 | M9: Under Review | N9: AA | O9: AA | P9: A | Q9: =_xlfn.XLOOKUP(N9,$W$3:$W$12,$X$3:$X$12) -> 8 | R9: =_xlfn.XLOOKUP(O9,$W$3:$W$12,$X$3:$X$12) -> 8 | S9: =_xlfn.XLOOKUP(P9,$W$3:$W$12,$X$3:$X$12) -> 6 | T9: =AVERAGE(Q9:S9) -> 7.3333333 | U9: =10 - _xlfn.PERCENTRANK.INC($K$3:$K$25,K9)*10 -> 7.28 | W9: Silver | X9: 8
A10: HDFC Flexi Cap Fund - Regular Plan | B10: 1.33 | C10: 34700 | D10: 96295 | G10: Franklin India Flexi Cap Fund - Growth | H10: Franklin India Flexi Cap Fund - Growth | I10: 0.000646 | J10: -0.001772 | K10: =B10 -> 1.33 | L10: =D10 -> 96295 | M10: Bronze | N10: AA | O10: AA | P10: A | Q10: =_xlfn.XLOOKUP(N10,$W$3:$W$12,$X$3:$X$12) -> 8 | R10: =_xlfn.XLOOKUP(O10,$W$3:$W$12,$X$3:$X$12) -> 8 | S10: =_xlfn.XLOOKUP(P10,$W$3:$W$12,$X$3:$X$12) -> 6 | T10: =AVERAGE(Q10:S10) -> 7.3333333 | U10: =10 - _xlfn.PERCENTRANK.INC($K$3:$K$25,K10)*10 -> 9.55 | W10: Bronze | X10: 6
A11: HSBC Flexi Cap Fund | B11: 1.93 | C11: 38041 | D11: 5227 | G11: PGIM India Flexi Cap Fund - Regular Plan - Growth Option | H11: PGIM India Flexi Cap Fund - Regular Plan - Gro... | I11: 0.000655 | J11: -0.002153 | K11: =B11 -> 1.93 | L11: =D11 -> 5227 | M11: Neutral | N11: A | O11: A | P11: AA | Q11: =_xlfn.XLOOKUP(N11,$W$3:$W$12,$X$3:$X$12) -> 6 | R11: =_xlfn.XLOOKUP(O11,$W$3:$W$12,$X$3:$X$12) -> 6 | S11: =_xlfn.XLOOKUP(P11,$W$3:$W$12,$X$3:$X$12) -> 8 | T11: =AVERAGE(Q11:S11) -> 6.6666667 | U11: =10 - _xlfn.PERCENTRANK.INC($K$3:$K$25,K11)*10 -> 2.28 | W11: Neutral | X11: 4
A12: JM Flexicap Fund | B12: 1.82 | C12: 39714 | D12: 5463 | G12: Aditya Birla Sun Life Flexi Cap Fund - Growth - Regular Plan | H12: Aditya Birla Sun Life Flexi Cap Fund - Growth ... | I12: 0.000608 | J12: -0.001752 | K12: =B12 -> 1.82 | L12: =D12 -> 5463 | M12: Neutral | N12: AA | O12: A | P12: A | Q12: =_xlfn.XLOOKUP(N12,$W$3:$W$12,$X$3:$X$12) -> 8 | R12: =_xlfn.XLOOKUP(O12,$W$3:$W$12,$X$3:$X$12) -> 6 | S12: =_xlfn.XLOOKUP(P12,$W$3:$W$12,$X$3:$X$12) -> 6 | T12: =AVERAGE(Q12:S12) -> 6.6666667 | U12: =10 - _xlfn.PERCENTRANK.INC($K$3:$K$25,K12)*10 -> 4.55 | W12: Negative | X12: 2
A13: Kotak Flexicap Fund - Regular Plan | B13: 1.44 | C13: 40067 | D13: 56460 | G13: BANDHAN Flexi Cap Fund - Regular Plan - Growth | H13: BANDHAN Flexi Cap Fund - Regular Plan - Growth | I13: 0.000518 | J13: -0.000543 | K13: =B13 -> 1.44 | L13: =D13 -> 56460 | M13: Neutral | N13: AA | O13: A | P13: A | Q13: =_xlfn.XLOOKUP(N13,$W$3:$W$12,$X$3:$X$12) -> 8 | R13: =_xlfn.XLOOKUP(O13,$W$3:$W$12,$X$3:$X$12) -> 6 | S13: =_xlfn.XLOOKUP(P13,$W$3:$W$12,$X$3:$X$12) -> 6 | T13: =AVERAGE(Q13:S13) -> 6.6666667 | U13: =10 - _xlfn.PERCENTRANK.INC($K$3:$K$25,K13)*10 -> 9.1
A14: LIC MF Flexi Cap Fund | B14: 2.27 | C14: 34074 | D14: 1063 | G14: CANARA ROBECO FLEXICAP FUND - REGULAR PLAN - GROWTH OPTION | H14: CANARA ROBECO FLEXICAP FUND - REGULAR PLAN - G... | I14: 0.000627 | J14: -0.001178 | K14: =B14 -> 2.27 | L14: =D14 -> 1063 | M14: Neutral | N14: A | O14: A | P14: A | Q14: =_xlfn.XLOOKUP(N14,$W$3:$W$12,$X$3:$X$12) -> 6 | R14: =_xlfn.XLOOKUP(O14,$W$3:$W$12,$X$3:$X$12) -> 6 | S14: =_xlfn.XLOOKUP(P14,$W$3:$W$12,$X$3:$X$12) -> 6 | T14: =AVERAGE(Q14:S14) -> 6 | U14: =10 - _xlfn.PERCENTRANK.INC($K$3:$K$25,K14)*10 -> 0.91
A15: Motilal Oswal Flexi Cap Fund - Regular Plan | B15: 1.71 | C15: 41757 | D15: 13862 | G15: Union Flexi Cap Fund - Growth Option | H15: Union Flexi Cap Fund - Growth Option | I15: 0.00063 | J15: -0.002113 | K15: =B15 -> 1.71 | L15: =D15 -> 13862 | M15: Neutral | N15: A | O15: A | P15: A | Q15: =_xlfn.XLOOKUP(N15,$W$3:$W$12,$X$3:$X$12) -> 6 | R15: =_xlfn.XLOOKUP(O15,$W$3:$W$12,$X$3:$X$12) -> 6 | S15: =_xlfn.XLOOKUP(P15,$W$3:$W$12,$X$3:$X$12) -> 6 | T15: =AVERAGE(Q15:S15) -> 6 | U15: =10 - _xlfn.PERCENTRANK.INC($K$3:$K$25,K15)*10 -> 6.37
A16: Navi Flexi Cap Fund - Regular Plan | B16: 2.23 | C16: 43290 | D16: 263 | G16: JM Flexicap Fund (Regular) - Growth option | H16: JM Flexicap Fund (Regular) - Growth option | I16: 0.000743 | J16: -0.001876 | K16: =B16 -> 2.23 | L16: =D16 -> 263 | M16: Neutral | N16: A | O16: A | P16: A | Q16: =_xlfn.XLOOKUP(N16,$W$3:$W$12,$X$3:$X$12) -> 6 | R16: =_xlfn.XLOOKUP(O16,$W$3:$W$12,$X$3:$X$12) -> 6 | S16: =_xlfn.XLOOKUP(P16,$W$3:$W$12,$X$3:$X$12) -> 6 | T16: =AVERAGE(Q16:S16) -> 6 | U16: =10 - _xlfn.PERCENTRANK.INC($K$3:$K$25,K16)*10 -> 1.37
A17: Parag Parikh Flexi Cap Fund - Regular Plan | B17: 1.28 | C17: 41418 | D17: 133309 | G17: DSP Flexi Cap Fund - Regular Plan - Growth | H17: DSP Flexi Cap Fund - Regular Plan - Growth | I17: 0.000644 | J17: -0.000982 | K17: =B17 -> 1.28 | L17: =D17 -> 133309 | M17: Neutral | N17: A | O17: BA | P17: A | Q17: =_xlfn.XLOOKUP(N17,$W$3:$W$12,$X$3:$X$12) -> 6 | R17: =_xlfn.XLOOKUP(O17,$W$3:$W$12,$X$3:$X$12) -> 4 | S17: =_xlfn.XLOOKUP(P17,$W$3:$W$12,$X$3:$X$12) -> 6 | T17: =AVERAGE(Q17:S17) -> 5.3333333 | U17: =10 - _xlfn.PERCENTRANK.INC($K$3:$K$25,K17)*10 -> 10
A18: PGIM India Flexi Cap Fund - Regular Plan | B18: 1.78 | C18: 42067 | D18: 6268 | G18: Axis Flexi Cap Fund - Regular Plan - Growth | H18: Axis Flexi Cap Fund - Regular Plan - Growth | I18: 0.000565 | J18: 3.6e-05 | K18: =B18 -> 1.78 | L18: =D18 -> 6268 | M18: Neutral | N18: BA | O18: A | P18: A | Q18: =_xlfn.XLOOKUP(N18,$W$3:$W$12,$X$3:$X$12) -> 4 | R18: =_xlfn.XLOOKUP(O18,$W$3:$W$12,$X$3:$X$12) -> 6 | S18: =_xlfn.XLOOKUP(P18,$W$3:$W$12,$X$3:$X$12) -> 6 | T18: =AVERAGE(Q18:S18) -> 5.3333333 | U18: =10 - _xlfn.PERCENTRANK.INC($K$3:$K$25,K18)*10 -> 5
A19: Quant Flexi Cap Fund | B19: 1.82 | C19: 39738 | D19: 6700 | G19: Navi Flexi Cap Fund - Regular Plan - Growth | H19: Navi Flexi Cap Fund - Regular Plan - Growth | I19: 0.00054 | J19: -0.000653 | K19: =B19 -> 1.82 | L19: =D19 -> 6700 | M19: Negative | N19: BA | O19: BA | P19: A | Q19: =_xlfn.XLOOKUP(N19,$W$3:$W$12,$X$3:$X$12) -> 4 | R19: =_xlfn.XLOOKUP(O19,$W$3:$W$12,$X$3:$X$12) -> 4 | S19: =_xlfn.XLOOKUP(P19,$W$3:$W$12,$X$3:$X$12) -> 6 | T19: =AVERAGE(Q19:S19) -> 4.6666667 | U19: =10 - _xlfn.PERCENTRANK.INC($K$3:$K$25,K19)*10 -> 4.55
A20: SBI Flexicap Fund | B20: 1.66 | C20: 38624 | D20: 23685 | G20: HSBC Flexi Cap Fund - Regular Growth | H20: HSBC Flexi Cap Fund - Regular Growth | I20: 0.000606 | J20: -0.000534 | K20: =B20 -> 1.66 | L20: =D20 -> 23685 | M20: Negative | N20: BA | O20: BA | P20: A | Q20: =_xlfn.XLOOKUP(N20,$W$3:$W$12,$X$3:$X$12) -> 4 | R20: =_xlfn.XLOOKUP(O20,$W$3:$W$12,$X$3:$X$12) -> 4 | S20: =_xlfn.XLOOKUP(P20,$W$3:$W$12,$X$3:$X$12) -> 6 | T20: =AVERAGE(Q20:S20) -> 4.6666667 | U20: =10 - _xlfn.PERCENTRANK.INC($K$3:$K$25,K20)*10 -> 8.19
A21: Shriram Flexi Cap Fund - Regular Plan | B21: 2.39 | C21: 43371 | D21: 137 | G21: Motilal Oswal Flexi Cap Fund Regular Plan-Growth Option | H21: Motilal Oswal Flexi Cap Fund Regular Plan-Grow... | I21: 0.000563 | J21: -0.001107 | K21: =B21 -> 2.39 | L21: =D21 -> 137 | M21: Negative | N21: BA | O21: BA | P21: BA | Q21: =_xlfn.XLOOKUP(N21,$W$3:$W$12,$X$3:$X$12) -> 4 | R21: =_xlfn.XLOOKUP(O21,$W$3:$W$12,$X$3:$X$12) -> 4 | S21: =_xlfn.XLOOKUP(P21,$W$3:$W$12,$X$3:$X$12) -> 4 | T21: =AVERAGE(Q21:S21) -> 4 | U21: =10 - _xlfn.PERCENTRANK.INC($K$3:$K$25,K21)*10 -> 0.46
A22: Tata Flexi Cap Fund - Regular Plan | B22: 1.89 | C22: 43349 | D22: 3699 | G22: Tata Flexi Cap Fund -Regular Plan-Growth | H22: Tata Flexi Cap Fund -Regular Plan-Growth | I22: 0.000542 | J22: -0.000859 | K22: =B22 -> 1.89 | L22: =D22 -> 3699 | M22: Negative | N22: BA | O22: BA | P22: BA | Q22: =_xlfn.XLOOKUP(N22,$W$3:$W$12,$X$3:$X$12) -> 4 | R22: =_xlfn.XLOOKUP(O22,$W$3:$W$12,$X$3:$X$12) -> 4 | S22: =_xlfn.XLOOKUP(P22,$W$3:$W$12,$X$3:$X$12) -> 4 | T22: =AVERAGE(Q22:S22) -> 4 | U22: =10 - _xlfn.PERCENTRANK.INC($K$3:$K$25,K22)*10 -> 3.19
A23: Taurus Flexi Cap Fund - Regular Plan | B23: 2.64 | C23: 34363 | D23: 357 | G23: Shriram Flexi Cap Fund - Regular Growth | H23: Shriram Flexi Cap Fund - Regular Growth | I23: 0.00041 | J23: -0.000443 | K23: =B23 -> 2.64 | L23: =D23 -> 357 | M23: Negative | N23: L | O23: BA | P23: BA | Q23: =_xlfn.XLOOKUP(N23,$W$3:$W$12,$X$3:$X$12) -> 2 | R23: =_xlfn.XLOOKUP(O23,$W$3:$W$12,$X$3:$X$12) -> 4 | S23: =_xlfn.XLOOKUP(P23,$W$3:$W$12,$X$3:$X$12) -> 4 | T23: =AVERAGE(Q23:S23) -> 3.3333333 | U23: =10 - _xlfn.PERCENTRANK.INC($K$3:$K$25,K23)*10 -> 0
A24: Union Flexi Cap Fund | B24: 2.02 | C24: 40704 | D24: 2402 | G24: Taurus Flexi Cap Fund - Regular Plan - Growth | H24: Taurus Flexi Cap Fund - Regular Plan - Growth | I24: 0.000494 | J24: -0.001386 | K24: =B24 -> 2.02 | L24: =D24 -> 2402 | M24: Negative | N24: L | O24: BA | P24: BA | Q24: =_xlfn.XLOOKUP(N24,$W$3:$W$12,$X$3:$X$12) -> 2 | R24: =_xlfn.XLOOKUP(O24,$W$3:$W$12,$X$3:$X$12) -> 4 | S24: =_xlfn.XLOOKUP(P24,$W$3:$W$12,$X$3:$X$12) -> 4 | T24: =AVERAGE(Q24:S24) -> 3.3333333 | U24: =10 - _xlfn.PERCENTRANK.INC($K$3:$K$25,K24)*10 -> 1.82
A25: UTI Flexi Cap Fund - Regular Plan | B25: 1.67 | C25: 33742 | D25: 24903 | G25: LIC MF Flexi Cap Fund-Regular Plan-Growth | H25: LIC MF Flexi Cap Fund-Regular Plan-Growth | I25: 0.000524 | J25: -0.001661 | K25: =B25 -> 1.67 | L25: =D25 -> 24903 | M25: Negative | N25: L | O25: BA | P25: BA | Q25: =_xlfn.XLOOKUP(N25,$W$3:$W$12,$X$3:$X$12) -> 2 | R25: =_xlfn.XLOOKUP(O25,$W$3:$W$12,$X$3:$X$12) -> 4 | S25: =_xlfn.XLOOKUP(P25,$W$3:$W$12,$X$3:$X$12) -> 4 | T25: =AVERAGE(Q25:S25) -> 3.3333333 | U25: =10 - _xlfn.PERCENTRANK.INC($K$3:$K$25,K25)*10 -> 7.73
G27: MAX | K27: =MAX(K3:K25) -> 2.64
G28: AVG | K28: =MIN(K3:K25) -> 1.28
G29: MIN | K29: =AVERAGE(K3:K25) -> 1.83
M32: exam

Sheet |

Sheet Extra I
A1: Expense Ratio and AUM
B2: Funds | C2: Net Assets (Cr) | D2: Expense Ratio (%) | E2: Launch | F2: Net Assets (Cr)2
B3: 360 ONE Flexicap Fund - Regular Plan | C3: =Table1[[#This Row],[Net Assets (Cr)2]] -> 2092 | D3: 1.99 | E3: 45107 | F3: 2092
B4: Abakkus Flexi Cap Fund - Regular Plan | C4: =Table1[[#This Row],[Net Assets (Cr)2]] -> 2493 | D4: 1.96 | E4: 46020 | F4: 2493
B5: Aditya Birla Sun Life Flexi Cap Fund - Regular Plan | C5: =Table1[[#This Row],[Net Assets (Cr)2]] -> 25098 | D5: 1.65 | E5: 36034 | F5: 25098
B6: Axis Flexi Cap Fund - Regular Plan | C6: =Table1[[#This Row],[Net Assets (Cr)2]] -> 13026 | D6: 1.72 | E6: 43059 | F6: 13026
B7: Bajaj Finserv Flexi Cap Fund - Regular Plan | C7: =Table1[[#This Row],[Net Assets (Cr)2]] -> 6342 | D7: 1.77 | E7: 45152 | F7: 6342
B8: Bandhan Flexi Cap Fund - Regular Plan | C8: =Table1[[#This Row],[Net Assets (Cr)2]] -> 7708 | D8: 1.85 | E8: 38623 | F8: 7708
B9: Bank of India Flexi Cap Fund - Regular Plan | C9: =Table1[[#This Row],[Net Assets (Cr)2]] -> 2244 | D9: 1.98 | E9: 44011 | F9: 2244
B10: Baroda BNP Paribas Flexi Cap Fund - Regular Plan | C10: =Table1[[#This Row],[Net Assets (Cr)2]] -> 1265 | D10: 2.18 | E10: 44790 | F10: 1265
B11: Canara Robeco Flexi Cap Fund - Regular Plan | C11: =Table1[[#This Row],[Net Assets (Cr)2]] -> 13760 | D11: 1.69 | E11: 37880 | F11: 13760
B12: Capitalmind Flexi Cap Fund - Regular Plan | C12: =Table1[[#This Row],[Net Assets (Cr)2]] -> 311 | D12: 2.37 | E12: 45873 | F12: 311
B13: DSP Flexi Cap Fund - Regular Plan | C13: =Table1[[#This Row],[Net Assets (Cr)2]] -> 12328 | D13: 1.72 | E13: 35549 | F13: 12328
B14: Edelweiss Flexi Cap Fund - Regular Plan | C14: =Table1[[#This Row],[Net Assets (Cr)2]] -> 3127 | D14: 1.89 | E14: 42038 | F14: 3127
... B45: WhiteOak Capital Flexi Cap Fund - Regular Plan | C45: =Table1[[#This Row],[Net Assets (Cr)2]] -> 7093 | D45: 1.77 | E45: 44775 | F45: 7093

Sheet Extra II
A1: Flexi Cap Fund (full universe)
B2: Funds | C2: Rating | D2: 1 Yr Ret (%) | E2: 1 Yr Rank | F2: Riskometer | G2: Category | H2: Analysts' View | I2: Expense Ratio (%) | J2: Launch | K2: Net Assets (Cr)
B3: 360 ONE Flexicap Fund - Regular Plan | C3: -- | D3: 2.7 | E3: 79/100 | F3: Very High | G3: EQ-FLX | H3: Unlock | I3: 1.99 | J3: 45107 | K3: 2092
B4: 360 ONE Focused Fund - Regular Plan | C4: 4 | D4: 5.05 | E4: 67/100 | F4: Very High | G4: EQ-FLX | H4: Unlock | I4: 1.79 | J4: 41942 | K4: 7229
B5: Abakkus Flexi Cap Fund - Regular Plan | C5: -- | D5: -- | E5: -- | F5: Very High | G5: EQ-FLX | H5: Unlock | I5: 1.96 | J5: 46020 | K5: 2493
B6: Aditya Birla Sun Life Bal Bhavishya Yojna - Regular Plan | C6: 2 | D6: 9.09 | E6: 21/100 | F6: Very High | G6: EQ-FLX | H6: Unlock | I6: 2.16 | J6: 43507 | K6: 1206
B7: Aditya Birla Sun Life Flexi Cap Fund - Regular Plan | C7: 3 | D7: 12.32 | E7: 9/100 | F7: Very High | G7: EQ-FLX | H7: Unlock | I7: 1.65 | J7: 36034 | K7: 25098
B8: Aditya Birla Sun Life Focused Fund - Regular Plan | C8: 3 | D8: 12.65 | E8: 7/100 | F8: Very High | G8: EQ-FLX | H8: Unlock | I8: 1.81 | J8: 38649 | K8: 8209
B9: Aditya Birla Sun Life Retirement Fund - The 30s Plan - Regular Plan | C9: 2 | D9: 12.27 | E9: 10/100 | F9: Very High | G9: EQ-FLX | H9: Unlock | I9: 2.41 | J9: 43535 | K9: 431
B10: Axis Flexi Cap Fund - Regular Plan | C10: 2 | D10: 5.89 | E10: 59/100 | F10: Very High | G10: EQ-FLX | H10: Unlock | I10: 1.72 | J10: 43059 | K10: 13026
B11: Axis Focused Fund | C11: 1 | D11: 5.69 | E11: 62/100 | F11: Very High | G11: EQ-FLX | H11: Unlock | I11: 1.75 | J11: 41089 | K11: 11972
B12: Bajaj Finserv Flexi Cap Fund - Regular Plan | C12: -- | D12: 8.16 | E12: 32/100 | F12: Very High | G12: EQ-FLX | H12: Unlock | I12: 1.77 | J12: 45152 | K12: 6342
B13: Bandhan Flexi Cap Fund - Regular Plan | C13: 3 | D13: 9.62 | E13: 18/100 | F13: Very High | G13: EQ-FLX | H13: Unlock | I13: 1.85 | J13: 38623 | K13: 7708
B14: Bandhan Focused Fund - Regular Plan | C14: 3 | D14: 2.25 | E14: 82/100 | F14: Very High | G14: EQ-FLX | H14: Unlock | I14: 2.05 | J14: 38792 | K14: 2059
B15: Bank of India Flexi Cap Fund - Regular Plan | C15: 4 | D15: 4.73 | E15: 70/100 | F15: Very High | G15: EQ-FLX | H15: Unlock | I15: 1.98 | J15: 44011 | K15: 2244
B16: Baroda BNP Paribas Children's Fund - Regular Plan | C16: -- | D16: 12.02 | E16: 12/100 | F16: Very High | G16: EQ-FLX | H16: Unlock | I16: 2.34 | J16: 45653 | K16: 110
B17: Baroda BNP Paribas Flexi Cap Fund - Regular Plan | C17: 3 | D17: 5.46 | E17: 64/100 | F17: Very High | G17: EQ-FLX | H17: Unlock | I17: 2.18 | J17: 44790 | K17: 1265
B18: Baroda BNP Paribas Focused Fund - Regular Plan | C18: 2 | D18: 5.79 | E18: 60/100 | F18: Very High | G18: EQ-FLX | H18: Unlock | I18: 2.28 | J18: 43014 | K18: 709
B19: Canara Robeco Flexi Cap Fund - Regular Plan | C19: 3 | D19: 8.85 | E19: 23/100 | F19: Very High | G19: EQ-FLX | H19: Unlock | I19: 1.69 | J19: 37880 | K19: 13760
B20: Canara Robeco Focused Fund - Regular Plan | C20: 4 | D20: 9.24 | E20: 19/100 | F20: Very High | G20: EQ-FLX | H20: Unlock | I20: 1.92 | J20: 44333 | K20: 2869
B21: Capitalmind Flexi Cap Fund - Regular Plan | C21: -- | D21: -- | E21: -- | F21: Very High | G21: EQ-FLX | H21: Unlock | I21: 2.37 | J21: 45873 | K21: 311
B22: DSP Flexi Cap Fund - Regular Plan | C22: 3 | D22: 6.21 | E22: 57/100 | F22: Very High | G22: EQ-FLX | H22: Unlock | I22: 1.72 | J22: 35549 | K22: 12328
B23: DSP Focused Fund - Regular Plan | C23: 3 | D23: 9.15 | E23: 20/100 | F23: Very High | G23: EQ-FLX | H23: Unlock | I23: 2.01 | J23: 40339 | K23: 2687
B24: Edelweiss Flexi Cap Fund - Regular Plan | C24: 4 | D24: 9.92 | E24: 17/100 | F24: Very High | G24: EQ-FLX | H24: Unlock | I24: 1.89 | J24: 42038 | K24: 3127
B25: Edelweiss Focused Fund - Regular Plan | C25: 3 | D25: 7.5 | E25: 42/100 | F25: Very High | G25: EQ-FLX | H25: Unlock | I25: 2.18 | J25: 44774 | K25: 1045
B26: Franklin India Flexi Cap Fund - Regular Plan | C26: 4 | D26: 6.11 | E26: 58/100 | F26: Very High | G26: EQ-FLX | H26: Unlock | I26: 1.69 | J26: 34606 | K26: 19972
B27: Franklin India Focused Equity Fund - Regular Plan | C27: 4 | D27: 8.25 | E27: 31/100 | F27: Very High | G27: EQ-FLX | H27: Unlock | I27: 1.77 | J27: 39289 | K27: 12649
B28: HDFC Flexi Cap Fund - Regular Plan | C28: 5 | D28: 13.5 | E28: 5/100 | F28: Very High | G28: EQ-FLX | H28: Unlock | I28: 1.33 | J28: 34700 | K28: 96295
B29: HDFC Focused Fund - Regular Plan | C29: 5 | D29: 12.49 | E29: 8/100 | F29: Very High | G29: EQ-FLX | H29: Unlock | I29: 1.6 | J29: 38247 | K29: 26537
B30: HDFC Retirement Savings Fund Equity Plan - Regular Plan | C30: 4 | D30: 6.34 | E30: 55/100 | F30: Very High | G30: EQ-FLX | H30: Unlock | I30: 1.76 | J30: 42425 | K30: 7086
B31: Helios Flexi Cap Fund - Regular Plan | C31: -- | D31: 9.08 | E31: 22/100 | F31: Very High | G31: EQ-FLX | H31: Unlock | I31: 1.8 | J31: 45243 | K31: 5932
B32: HSBC Flexi Cap Fund | C32: 4 | D32: 5.7 | E32: 61/100 | F32: Very High | G32: EQ-FLX | H32: Unlock | I32: 1.93 | J32: 38041 | K32: 5227
B33: HSBC Focused Fund - Regular Plan | C33: 2 | D33: 6.29 | E33: 56/100 | F33: Very High | G33: EQ-FLX | H33: Unlock | I33: 2.11 | J33: 44034 | K33: 1718
B34: ICICI Prudential Flexicap Fund | C34: 4 | D34: 10.88 | E34: 14/100 | F34: Very High | G34: EQ-FLX | H34: Unlock | I34: 1.68 | J34: 44394 | K34: 20135
B35: ICICI Prudential Focused Equity Fund | C35: 5 | D35: 18.35 | E35: 1/100 | F35: Very High | G35: EQ-FLX | H35: Unlock | I35: 1.69 | J35: 39961 | K35: 14569
B36: ICICI Prudential Retirement Fund - Pure Equity Plan | C36: 5 | D36: 15.12 | E36: 4/100 | F36: Very High | G36: EQ-FLX | H36: Unlock | I36: 2.03 | J36: 43523 | K36: 1642
B37: Invesco India Flexi Cap Fund - Regular Plan | C37: 5 | D37: 5.18 | E37: 66/100 | F37: Very High | G37: EQ-FLX | H37: Unlock | I37: 1.85 | J37: 44606 | K37: 4723
B38: Invesco India Focused Fund - Regular Plan | C38: 4 | D38: -0.7 | E38: 93/100 | F38: Very High | G38: EQ-FLX | H38: Unlock | I38: 1.83 | J38: 44103 | K38: 4912
B39: ITI Flexi Cap Fund - Regular Plan | C39: -- | D39: 7.59 | E39: 41/100 | F39: Very High | G39: EQ-FLX | H39: Unlock | I39: 2.02 | J39: 44974 | K39: 1299
B40: ITI Focused Fund - Regular Plan | C40: -- | D40: 12.08 | E40: 11/100 | F40: Very High | G40: EQ-FLX | H40: Unlock | I40: 2.33 | J40: 45096 | K40: 573
...
